Workbook
Name RangoDinamico: DESREF(Albums!#REF!,0,0,Albums!$AF$3,1)

Sheet GUÍA
A1: Este excel lo empecé el 17 de enero de 2026 con el objetivo de hacer 1000 reviews de álbumes | P1: 10.5
A2: Escribo esta guía por si en algún futuro se me olvida como funciona | O2: >8,9 | P2: 10
O3: >8,8 | P3: 9.5
A4: FLUJO DE REVIEW | O4: >8,7 | P4: 9
A5: 1. Hacer la review en la hoja Albums | O5: >8,5 | P5: 8.5
A6: 1.1 Todos los álbumes empiezan con un header así: * <Artista> - <Nombre álbum> | O6: >8 | P6: 8
A7: 1.2 El asterisco es obligatorio, sin él, el script ignora el álbum | O7: >7,5 | P7: 7.5
A8: 1.3 El guion separando el artista y el álbum también es obligatorio | O8: >7 | P8: 7
A9: 1.4 Esto implica que ni el artista ni el álbum pueden contener esos dos símbolos
A10: 1.5 En la celda justo debajo de la última canción (la que antes se dejaba vacía) escribir la línea de info:
A11: <año>, <subgéneros separados por comas>, <duración>
A12: Ejemplo: 1972, progressive rock, art rock, 1h 2m
A13: 1.6 Subgéneros: suelo poner los géneros principales del álbum que salgan en RYM.com (el script los pasa a minúsculas)
A14: 1.7 Duración con el formato <horas>h <minutos>m, o solo <minutos>m si dura menos de una hora
A15: 1.8 Las tres partes son obligatorias: si falta alguna, el script no rellena nada, deja la línea en su celda y avisa en el log
A16: 2. Ejecutar el script
A17: 2.1 Se hace en la pestaña Automatización -> Ver Scripts -> Scripts Recientes -> Create Tables -> Run
A18: 2.2 Este script está guardado en mi cuenta de OneDrive
A19: 2.3 Si por alguna razón no está visible, el script está también guardado en un repo de GitHub: https://github.com/miguelrr11/top1000albums
A20: 2.4 El script añade el álbum a Tabla Albums con año, subgéneros, duración y fecha de review (la de hoy, dd/mm/aaaa), y vacía la celda de la línea de info
... A27: 4. Hacer push en el repo de GitHub (el repo contiene el script pero también contiene el Excel)
H28: NOTAS: No es obligatorio ejecutar el script, se puede hacer cuando se quiera, no hay problema por hacer 5 reviews y luego ejecutarlo
A29: Resumen Hojas: | H29: - La fecha de review es el día en que ejecutas el script. Si hiciste la review otro día, cámbiala a mano en Tabla Albums.
A30: Hoja | B30: Tipo | C30: Razón | H30: - Para corregir un álbum ya reseñado: edita Tabla Albums directamente o escribe otra línea de info debajo del álbum.
A31: Albums | B31: MANUAL | C31: Se hacen las reviews | H31: La línea nueva sobrescribe año, subgéneros y duración, pero mantiene la fecha de review original.
A32: Tabla Albums | B32: SEMIAUTOMÁTICO | C32: Se rellana manualmente metadatos
A33: Tablas TOP | B33: AUTOMÁTICO
A34: TOP Canciones | B34: AUTOMÁTICO
A35: TOP Generos | B35: AUTOMÁTICO
A36: Mapeo Generos | B36: SEMIAUTOMÁTICO | C36: Se rellena manualmente subgeneros sin genero padre
A37: Resumen | B37: AUTOMÁTICO
A39: NOTAS
A40: El thirdEyeScore fue un intento de mejorar la nota de un álbum, en vez de ser simplemente la media de las canciones, también penaliza si
A41: la desviación es grande y recompensa álbumes con dieces
A43: La tabla de la hoja Tabla Albums se ordena por defecto por el valor thirdEyeScore, pero si se quiere ordenar por cualquier otra cosa, hay que
A44: quitar el asterisco del header de thirdeyescore, ponerlo en el header por el que se quiere ordenar la tabla, y ejecutar el script
A46: Algunas hojas no pasa nada si se modifican y otras no:
A47: Hoja | B47: Tipo | C47: Razón
A48: Albums | B48: VULNERABLE | C48: Es la fuente de verdad, si le pasa algo el resto de hojas se ven afectadas
A49: Tabla Albums | B49: SEMI-VULNERABLE | C49: Las columnas que se rellenan manualmente son vulnerables, si se eliminan, no hay manera de recuperarlas
...

Sheet Albums
A2: * TOOL - Lateralus | B2: =ROUND(SUM(B3:B14)/COUNT(B3:B14), 2) -> 10.11 | D2: * Radiohead - In Rainbows | E2: =ROUND(SUM(E3:E12)/COUNT(E3:E12), 2) -> 9.7 | G2: * Sweet Trip - You Will Never Know Why | H2: =ROUND(SUM(H3:H15)/COUNT(H3:H15), 2) -> 8.88 | J2: * The Alan Parsons Project - Eye In The Sky | K2: =ROUND(SUM(K3:K12)/COUNT(K3:K12), 2) -> 9.15 | M2: * Pink Floyd - The Dark Side Of The Moon | N2: =ROUND(SUM(N3:N12)/COUNT(N3:N12), 2) -> 9.61
A3: The Grudge | B3: 10.5 | D3: 15 Step | E3: 10 | G3: Conversation of Two | H3: 9 | J3: Sirius | K3: 9.5 | M3: Speak to Me
A4: Eon Blue Apocalypse | D4: Bodysnatchers | E4: 9 | G4: Air Supply | H4: 9 | J4: Eye In The Sky | K4: 10 | M4: Breath (In the Air) | N4: 9
A5: The Patient | B5: 10 | D5: Nude | E5: 10.5 | G5: Forever | H5: 8 | J5: Children of the Moon | K5: 8.5 | M5: On the Run | N5: 7.5
A6: Mantra | D6: Weird Fishes / Arpeggi | E6: 10.5 | G6: Acting | H6: 10 | J6: Gemini | K6: 8 | M6: Time | N6: 10.5
A7: Schsim | B7: 10.5 | D7: All I Need | E7: 10 | G7: Milk | H7: 10.5 | J7: Silence and I | K7: 10.5 | M7: The Great Gig in the Sky | N7: 10.5
A8: Parabol(a) | B8: 10.5 | D8: Faust Arp | E8: 8.5 | G8: Darkness | H8: 10.5 | J8: You're Gonna Get Your Fingers Burned | K8: 8.5 | M8: Money | N8: 10
A9: Ticks & Leeches | B9: 9.5 | D9: Reckoner | E9: 10.5 | G9: To the Moon | H9: 9 | J9: Psychobabble | K9: 9 | M9: Us and Them | N9: 10
A10: Lateralus | B10: 10.5 | D10: House Of Cards | E10: 9.5 | G10: Song About a Sea | H10: 7.5 | J10: Mammagamma | K10: 9 | M10: Any Colour You Like | N10: 9
A11: Disposition | B11: 9 | D11: Jigsaw Fallin Into Place | E11: 10.5 | G11: Song About a Sun | H11: 8 | J11: Step by Step | K11: 8.5 | M11: Brain Damage | N11: 10
A12: Reflection | B12: 10.5 | D12: Videotape | E12: 8 | G12: No Words to Be Found | H12: 8 | J12: Old And Wise | K12: 10 | M12: Eclipse | N12: 10
A13: Triad | B13: 10 | G13: Pretending | H13: 9
A14: Faaip De Oiad | D14: * Daft Punk - Discovery | E14: =ROUND(SUM(E15:E28)/COUNT(E15:E28), 2) -> 9 | G14: Misfortunes are Cruel | H14: 8.5 | J14: * Dire Straits - Brothers In Arms | K14: =ROUND(SUM(K15:K23)/COUNT(K15:K23), 2) -> 8.94 | M14: * Fleetwood Mac - Rumours | N14: =ROUND(SUM(N15:N26)/COUNT(N15:N26), 2) -> 8.71
D15: One More Time | E15: 9 | G15: Your World is Eternally Complete | H15: 8.5 | J15: So Far Away | K15: 9.5 | M15: Second Hand News | N15: 9
A16: * Metallica - Master Of Puppets | B16: =ROUND(SUM(B17:B24)/COUNT(B17:B24), 2) -> 9.25 | D16: Aerodynamic | E16: 10.5 | J16: Money For Nothing | K16: 10 | M16: Dreams | N16: 10
A17: Battery | B17: 9.5 | D17: Digital Love | E17: 10 | G17: * Massive Attack - Mezzanine | H17: =ROUND(SUM(H18:H28)/COUNT(H18:H28), 2) -> 8.77 | J17: Walk Of Life | K17: 9.5 | M17: Never Going Back Again | N17: 8
A18: Master Of Puppets | B18: 10 | D18: Harder, Better, Faster, Stonger | E18: 9.5 | G18: Angel | H18: 10 | J18: Your Latest Trick | K18: 9 | M18: Don't Stop | N18: 8.5
A19: The Thing That Should Not Be | B19: 8.5 | D19: Crescendolls | E19: 8.5 | G19: Risingson | H19: 9 | J19: Why Worry? | K19: 7.5 | M19: Go Your Own Way | N19: 8.5
A20: Welcome Home (Sanitarium) | B20: 10 | D20: Nightvision | G20: Teardrop | H20: 10 | J20: Ride Across The River | K20: 8 | M20: Songbird | N20: 7.5
A21: Disposable Heroes | B21: 8.5 | D21: Superheroes | E21: 9 | G21: Inertia Creeps | H21: 9 | J21: The Man's Too Strong | K21: 8.5 | M21: The Chain | N21: 10
A22: Leper Messiah | B22: 9 | D22: High Life | E22: 8 | G22: Exchange | H22: 8 | J22: One World | K22: 8 | M22: You Make Loving Fun | N22: 9
A23: Orion | B23: 10.5 | D23: Something About Us | E23: 10 | G23: Dissolved Girl | H23: 8.5 | J23: Brothers In Arms | K23: 10.5 | M23: I Don't Want to Know | N23: 8.5
A24: Damage, Inc. | B24: 8 | D24: Voyager | E24: 8.5 | G24: Man Next Door | H24: 8 | M24: Oh Daddy | N24: 7.5
D25: Veridis Quo | E25: 9.5 | G25: Black Milk | H25: 10 | J25: * Linkin Park - Hybrid Theory | K25: =ROUND(SUM(K26:K38)/COUNT(K26:K38), 2) -> 8.42 | M25: Gold Dust Woman | N25: 9
A26: * King Crimson - In The Court Of The Crimson King | B26: =ROUND(SUM(B27:B31)/COUNT(B27:B31), 2) -> 9.4 | D26: Short Circuit | E26: 8 | G26: Mezzazine | H26: 7.5 | J26: Papercut | K26: 10 | M26: Silver Springs | N26: 9
A27: 21st Century Schizoid Man | B27: 10 | D27: Face to Face | E27: 9 | G27: Group Four | H27: 8.5 | J27: One Step Closer | K27: 9.5
A28: I Talk To The Wind | B28: 9 | D28: Too Long | E28: 7.5 | G28: (Exchange) | H28: 8 | J28: With You | K28: 8.5 | M28: * The Strokes - The New Abnormal | N28: =ROUND(SUM(N29:N37)/COUNT(N29:N37), 2) -> 8.89
A29: Epitaph | B29: 10.5 | J29: Points of Authority | K29: 8.5 | M29: The Adults Are Talking | N29: 10
A30: Moonchild | B30: 8.5 | D30: * Opeth - Blackwater Park | E30: =ROUND(SUM(E31:E37)/COUNT(E31:E37), 2) -> 9.29 | G30: * TOOL - Ænima | H30: =ROUND(SUM(H31:H45)/COUNT(H31:H45), 2) -> 9.61 | J30: Crawling | K30: 9.5 | M30: Selfless | N30: 9
A31: The Court Of The Crimson King | B31: 9 | D31: The Lepper Affinity | E31: 9.5 | G31: Stinkfist | H31: 10 | J31: Runaway | K31: 8.5 | M31: Brooklyn Bridge To Chorus | N31: 8
D32: Bleak | E32: 10 | G32: Eulogy | H32: 10.5 | J32: By Myself | K32: 7.5 | M32: Bad Decisions | N32: 8.5
A33: * Radiohead - OK Computer | B33: =ROUND(SUM(B34:B45)/COUNT(B34:B45), 2) -> 9.68 | D33: Harvest | E33: 9 | G33: H. | H33: 10 | J33: In The End | K33: 9 | M33: Eternal Summer | N33: 9
A34: Airbag | B34: 9 | D34: The Drapery Falls | E34: 10.5 | G34: Useful Idiot | J34: A Place for My Head | K34: 8 | M34: At The Door | N34: 8
A35: Paranoid Android | B35: 10.5 | D35: Dirge For November | E35: 9.5 | G35: Forty Six & 2 | H35: 10.5 | J35: Forgotten | K35: 7 | M35: Why Are Sundays So Depressing | N35: 9
A36: Subterranean Homesick Alien | B36: 9.5 | D36: The Funeral Portrait | E36: 8 | G36: Message To Harry Manback | J36: Cure For The Itch | M36: Not The Same Anymore | N36: 8.5
A37: Exit Music (For a Film) | B37: 10 | D37: Blackwater Park | E37: 8.5 | G37: Hooker With A Penis | H37: 8.5 | J37: Pushing Me Away | K37: 7.5 | M37: Ode To The Mets | N37: 10
A38: Let Down | B38: 10.5 | G38: Intermission | J38: My December | K38: 7.5
A39: Karma Police | B39: 9.5 | D39: * Coldplay - X&Y | E39: =ROUND(SUM(E40:E52)/COUNT(E40:E52), 2) -> 8.65 | G39: Jimmy | H39: 9 | M39: * Have A Nice Life - Deathconsciousness | N39: =ROUND(SUM(N40:N52)/COUNT(N40:N52), 2) -> 9.21
A40: Fitter Happier | D40: Square One | E40: 8.5 | G40: Die Eir Von Satan | J40: * Alice In Chains - Dirt | K40: =ROUND(SUM(K41:K52)/COUNT(K41:K52), 2) -> 8.38 | M40: A Quick One Before the Eternal Worm Devours Connecticut | N40: 10
A41: Electioneering | B41: 9 | D41: What If | E41: 9 | G41: Pushit | H41: 10 | J41: Them Bones | K41: 9 | M41: Bloodhail | N41: 9.5
...

Sheet Tabla Albums
A1: ÁLBUMES
A2: # | B2: Artista | C2: Álbum | D2: Media | E2: 3rd EYE SCORE | F2: Mediana | G2: Desv. Típica | H2: Notas ≥10 | I2: Total Canciones | J2: Interludios | K2: Subgéneros | L2: Año | M2: Duración | N2: Fecha de review *
A3: 1 | B3: Prince | C3: Purple Rain | D3: 8.94 | E3: 8.95 | F3: 8.5 | G3: 0.96 | H3: 3 | I3: 9 | J3: 0 | K3: pop rock | L3: 1984 | M3: 43m | N3: 05/10/2026
A4: 2 | B4: Cocteau Twins | C4: Treasure | D4: 8.55 | E4: 8.47 | F4: 8.5 | G4: 0.52 | H4: 0 | I4: 10 | J4: 0 | K4: dream pop, ethereal wave | L4: 1984 | M4: 41m | N4: 04/10/2026
A5: 3 | B5: Electric Light Orchestra | C5: Discovery | D5: 8.56 | E5: 8.61 | F5: 8.5 | G5: 0.83 | H5: 1 | I5: 9 | J5: 0 | K5: pop rock | L5: 1979 | M5: 38m | N5: 02/10/2026
A6: 4 | B6: Queens of the Stone Age | C6: …Like Clockwork | D6: 8.95 | E6: 8.92 | F6: 9 | G6: 0.61 | H6: 2 | I6: 10 | J6: 0 | K6: alternative rock | L6: 2013 | M6: 46m | N6: 30/09/2026
A7: 5 | B7: Milo J | C7: La Vida Era Más Corta | D7: 8.17 | E7: 8.08 | F7: 8 | G7: 0.43 | H7: 0 | I7: 15 | J7: 0 | K7: art pop | L7: 2025 | M7: 48m | N7: 29/09/2026
A8: 6 | B8: Childish Gambino | C8: "Awaken, My Love!" | D8: 8.23 | E8: 8.21 | F8: 8 | G8: 1.23 | H8: 2 | I8: 11 | J8: 0 | K8: psychedelic soul, funk | L8: 2016 | M8: 49m | N8: 27/09/2026
A9: 7 | B9: The Caretaker | C9: Everywhere at the End of Time (Stage 3) | D9: 8.09 | E9: 8 | F9: 8 | G9: 0.57 | H9: 0 | I9: 16 | J9: 0 | K9: ambient, hauntology | L9: 2017 | M9: 45m | N9: 27/09/2026
A10: 8 | B10: The Caretaker | C10: Everywhere at the End of Time (Stage 4) | D10: 8 | E10: 7.96 | F10: 8 | G10: 0.35 | H10: 0 | I10: 4 | J10: 0 | K10: dark ambient, hauntology | L10: 2018 | M10: 1h 27m | N10: 27/09/2026
A11: 9 | B11: The Caretaker | C11: Everywhere at the End of Time (Stage 5) | D11: 7.88 | E11: 7.8 | F11: 7.75 | G11: 0.41 | H11: 0 | I11: 4 | J11: 0 | K11: dark ambient, noise | L11: 2018 | M11: 1h 28m | N11: 27/09/2026
A12: 10 | B12: The Caretaker | C12: Everywhere at the End of Time (Stage 6) | D12: 8.63 | E12: 8.5 | F12: 8.25 | G12: 0.82 | H12: 1 | I12: 4 | J12: 0 | K12: dark ambient, drone | L12: 2019 | M12: 1h 25m | N12: 27/09/2026
A13: 11 | B13: Napalm Death | C13: Scum | D13: 7.13 | E13: 6.97 | F13: 7 | G13: 1.08 | H13: 0 | I13: 28 | J13: 1 | K13: grindore | L13: 1987 | M13: 33m | N13: 26/09/2026
A14: 12 | B14: The Caretaker | C14: Everywhere at the End of Time (Stage 1) | D14: 8.17 | E14: 8.05 | F14: 8 | G14: 0.77 | H14: 1 | I14: 12 | J14: 0 | K14: ambient, hauntology | L14: 2016 | M14: 41m | N14: 26/09/2026
... A149: 147 | B149: Morbid Angel | C149: Altars of Madness | D149: 8.4 | E149: 8.3 | F149: 8.25 | G149: 0.73 | H149: 1 | I149: 10 | J149: 0 | K149: death metal | L149: 1989 | M149: 46m | N149: 26/05/2026
A150: 148 | B150: Foreigner | C150: 4 | D150: 8.6 | E150: 8.6 | F150: 8.25 | G150: 0.97 | H150: 2 | I150: 10 | J150: 0 | K150: aor, hard rock | L150: 1981 | M150: 41m | N150: 25/05/2026
A151: 149 | B151: Rainbow | C151: Rising | D151: 8.58 | E151: 8.5 | F151: 8.5 | G151: 0.79 | H151: 1 | I151: 6 | J151: 0 | K151: hard rock, heavy metal | L151: 1976 | M151: 33m | N151: 25/05/2026
A152: 150 | B152: A Perfect Circle | C152: Thirteenth Step | D152: 8.41 | E152: 8.24 | F152: 8 | G152: 0.95 | H152: 2 | I152: 12 | J152: 1 | K152: alternative rock, alternative metal | L152: 2003 | M152: 50m | N152: 24/05/2026
A153: 151 | B153: Deftones | C153: White Pony | D153: 8.96 | E153: 8.92 | F153: 9 | G153: 0.75 | H153: 3 | I153: 12 | J153: 0 | K153: alternative metal | L153: 2000 | M153: 52m | N153: 24/05/2026
A154: 152 | B154: Barry B | C154: CHATO | D154: 8.25 | E154: 8.18 | F154: 8.25 | G154: 0.6 | H154: 0 | I154: 12 | J154: 0 | K154: alt pop | L154: 2024 | M154: 34m | N154: 22/05/2026
A155: 153 | B155: black midi | C155: Hellfire | D155: 8.44 | E155: 8.39 | F155: 8.5 | G155: 0.55 | H155: 0 | I155: 10 | J155: 1 | K155: avant prog, brutal prog | L155: 2022 | M155: 38m | N155: 22/05/2026
A156: 154 | B156: The Beatles | C156: Revolver | D156: 8.39 | E156: 8.39 | F156: 8 | G156: 0.83 | H156: 2 | I156: 14 | J156: 0 | K156: pop rock, psychedelic pop | L156: 1966 | M156: 34m | N156: 21/05/2026
A157: 155 | B157: Pink Floyd | C157: The Wall | D157: 8.8 | E157: 8.97 | F157: 8.5 | G157: 0.73 | H157: 3 | I157: 26 | J157: 4 | K157: rock opera, art rock | L157: 1979 | M157: 1h 21m | N157: 21/05/2026
A158: 156 | B158: Slayyyter | C158: WOR$T GIRL IN AMERICA | D158: 8.65 | E158: 8.56 | F158: 8.5 | G158: 0.77 | H158: 2 | I158: 14 | J158: 1 | K158: electropop, electroclash | L158: 2026 | M158: 42m | N158: 20/05/2026
A159: 157 | B159: Dire Straits | C159: Love Over Gold | D159: 8.8 | E159: 8.81 | F159: 8.5 | G159: 0.93 | H159: 1 | I159: 5 | J159: 0 | K159: art rock | L159: 1982 | M159: 41m | N159: 19/05/2026
A160: 158 | B160: Justice | C160: Justice | D160: 8.63 | E160: 8.54 | F160: 8.5 | G160: 0.71 | H160: 2 | I160: 12 | J160: 0 | K160: french electro | L160: 2007 | M160: 48m | N160: 18/05/2026
A161: 159 | B161: System Of A Down | C161: Toxicity | D161: 8.83 | E161: 9 | F161: 8.5 | G161: 0.87 | H161: 3 | I161: 15 | J161: 0 | K161: alternative metal | L161: 2001 | M161: 44m | N161: 18/05/2026
A162: 160 | B162: Kanye West | C162: The College Dropout | D162: 8.73 | E162: 8.62 | F162: 8.5 | G162: 0.57 | H162: 1 | I162: 21 | J162: 6 | K162: chipmunk soul, pop rap | L162: 2004 | M162: 1h 16m | N162: 18/05/2026
... A337: 335 | B337: Opeth | C337: Blackwater Park | D337: 9.29 | E337: 9.44 | F337: 9.5 | G337: 0.8 | H337: 2 | I337: 7 | J337: 0 | K337: progressive metal, death metal | L337: 2001 | M337: 1h 16m | N337: 17/01/2026

Sheet Tablas TOP
A1: RESUMEN ARTISTAS REPETIDOS
A2: # | B2: Artista | C2: Álbumes | D2: Media | E2: 3rd EYE SCORE * | F2: Mediana | G2: Desv. Típica | H2: Notas ≥10 | I2: Total Canciones | J2: Interludios | K2: Subgéneros | L2: Año | M2: Duración | N2: Fecha de review
A3: 1 | B3: Fishmans | C3: 2 | D3: 9.75 | E3: 9.88 | F3: 9.63 | G3: 0.36 | H3: 3 | I3: 9 | J3: 0 | K3: neo psychedelic, dream pop, dowmtempo | L3: 1996 - 1997 | M3: 47m | N3: -
A4: 2 | B4: Pink Floyd | C4: 5 | D4: 9.35 | E4: 9.58 | F4: 9.35 | G4: 0.76 | H4: 16 | I4: 52 | J4: 5 | K4: progressive rock, psychedelic rock, art rock, rock opera | L4: 1971 - 1979 | M4: 51m | N4: -
A5: 3 | B5: TOOL | C5: 7 | D5: 9.16 | E5: 9.42 | F5: 9.39 | G5: 0.89 | H5: 26 | I5: 72 | J5: 16 | K5: progressive metal, alternative metal, post metal | L5: 1992 - 2019 | M5: 1h 9m | N5: -
A6: 4 | B6: Extremoduro | C6: 2 | D6: 9.21 | E6: 9.37 | F6: 9.38 | G6: 0.85 | H6: 5 | I6: 12 | J6: 0 | K6: hard rock, progressive rock, art rock | L6: 2008 - 2011 | M6: 44m | N6: -
A7: 5 | B7: Godspeed You! Black Emperor | C7: 3 | D7: 9.24 | E7: 9.28 | F7: 9.25 | G7: 0.32 | H7: 2 | I7: 12 | J7: 0 | K7: post rock | L7: 1997 - 2002 | M7: 1h 15m | N7: -
A8: 6 | B8: Led Zeppelin | C8: 3 | D8: 9.04 | E8: 9.06 | F8: 8.92 | G8: 0.92 | H8: 8 | I8: 26 | J8: 0 | K8: classic rock, folk rock, hard rock | L8: 1970 - 1973 | M8: 42m | N8: -
A9: 7 | B9: Sweet Trip | C9: 2 | D9: 8.94 | E9: 9.05 | F9: 9 | G9: 0.77 | H9: 5 | I9: 25 | J9: 0 | K9: dream pop, indie pop, idm, glitch pop | L9: 2003 - 2009 | M9: 1h 5m | N9: -
A10: 8 | B10: Yes | C10: 3 | D10: 8.91 | E10: 8.99 | F10: 9 | G10: 0.69 | H10: 3 | I10: 15 | J10: 1 | K10: progressive rock, symphonic prog | L10: 1971 - 1974 | M10: 40m | N10: -
A11: 9 | B11: Porcupine Tree | C11: 4 | D11: 8.91 | E11: 8.97 | F11: 8.75 | G11: 0.81 | H11: 7 | I11: 37 | J11: 0 | K11: progressive rock, progressive metal, post britpop | L11: 2000 - 2007 | M11: 59m | N11: -
A12: 10 | B12: Dire Straits | C12: 3 | D12: 8.86 | E12: 8.9 | F12: 8.67 | G12: 0.9 | H12: 5 | I12: 23 | J12: 0 | K12: classic rock, roots rock, blues rock, art rock | L12: 1978 - 1985 | M12: 45m | N12: -
A13: 11 | B13: C418 | C13: 2 | D13: 8.72 | E13: 8.9 | F13: 8.5 | G13: 0.94 | H13: 10 | I13: 54 | J13: 2 | K13: ambient, video game music | L13: 2011 - 2013 | M13: 1h 39m | N13: -
A14: 12 | B14: King Crimson | C14: 5 | D14: 8.9 | E14: 8.88 | F14: 8.75 | G14: 0.69 | H14: 5 | I14: 32 | J14: 0 | K14: progressive rock, art rock, avant prog | L14: 1969 - 2024 | M14: 44m | N14: -
... A57: 55 | B57: The Strokes | C57: 3 | D57: 7.71 | E57: 7.61 | F57: 7.67 | G57: 0.92 | H57: 3 | I57: 29 | J57: 0 | K57: garage rock, indie rock, garage rock revival | L57: 2001 - 2026 | M57: 41m | N57: -
A59: TOP 25 (sin repetir artistas y sin incluir OSTs, LIVEs y SINGLEs)
A60: # | B60: Artista | C60: Álbum | D60: Media | E60: 3rd EYE SCORE
A61: 1 | B61: TOOL | C61: Lateralus | D61: 10.11 | E61: 10.99
A62: 2 | B62: Fishmans | C62: LONG SEASON | D62: 10.5 | E62: 10.85
A63: 3 | B63: Yes | C63: Close to the Edge | D63: 10 | E63: 10.44
A64: 4 | B64: Radiohead | C64: In Rainbows | D64: 9.7 | E64: 10.37
A65: 5 | B65: Godspeed You! Black Emperor | C65: Lift Yr. Skinny Fists Like Antennas to Heaven! | D65: 9.88 | E65: 10.05
A66: 6 | B66: Pink Floyd | C66: The Dark Side Of The Moon | D66: 9.61 | E66: 10
A67: 7 | B67: Extremoduro | C67: La ley innata | D67: 9.5 | E67: 9.77
A68: 8 | B68: Led Zeppelin | C68: Led Zeppelin IV | D68: 9.38 | E68: 9.53
A69: 9 | B69: King Crimson | C69: In The Court Of The Crimson King | D69: 9.4 | E69: 9.46
A70: 10 | B70: Opeth | C70: Blackwater Park | D70: 9.29 | E70: 9.44
A71: 11 | B71: Black Sabbath | C71: Paranoid | D71: 9.31 | E71: 9.43
A72: 12 | B72: Metallica | C72: Master Of Puppets | D72: 9.25 | E72: 9.37
... A85: 25 | B85: Robe | C85: Mayéutica | D85: 9.08 | E85: 9.03
A87: TOP 25 (sin reglas)
A88: # | B88: Artista | C88: Álbum | D88: Media | E88: 3rd EYE SCORE
A89: 1 | B89: TOOL | C89: Lateralus | D89: 10.11 | E89: 10.99
A90: 2 | B90: Fishmans | C90: LONG SEASON | D90: 10.5 | E90: 10.85
A91: 3 | B91: Yes | C91: Close to the Edge | D91: 10 | E91: 10.44
A92: 4 | B92: Pink Floyd | C92: Wish You Were Here | D92: 10 | E92: 10.39
A93: 5 | B93: Radiohead | C93: In Rainbows | D93: 9.7 | E93: 10.37
A94: 6 | B94: Radiohead | C94: OK Computer | D94: 9.68 | E94: 10.07
A95: 7 | B95: Godspeed You! Black Emperor | C95: Lift Yr. Skinny Fists Like Antennas to Heaven! | D95: 9.88 | E95: 10.05
A96: 8 | B96: Pink Floyd | C96: The Dark Side Of The Moon | D96: 9.61 | E96: 10
...

Sheet TOP Canciones
A1: TOP 100 CANCIONES [10.5: 100] (máx. 2 por álbum) | G1: AJUSTES
A2: # | B2: Canción | C2: Álbum | D2: Artista | E2: Subgénero | G2: Canciones totales | H2: 100
A3: 1 | B3: Schsim | C3: Lateralus | D3: TOOL | E3: progressive metal, alternative metal | G3: Canciones por álbum | H3: 2
A4: 2 | B4: Lateralus | C4: Lateralus | D4: TOOL | E4: progressive metal, alternative metal | G4: Canciones por artista
A5: 3 | B5: LONG SEASON | C5: LONG SEASON | D5: Fishmans | E5: neo psychedelic, dream pop | G5: Randomizar en empate | H5: SI
A6: 4 | B6: Close to the Edge | C6: Close to the Edge | D6: Yes | E6: progressive rock | G6: Incluir Géneros
A7: 5 | B7: Siberian Khatru | C7: Close to the Edge | D7: Yes | E7: progressive rock | G7: Excluir Subgéneros
A8: 6 | B8: Wish You Were Here | C8: Wish You Were Here | D8: Pink Floyd | E8: progressive rock, art rock
A9: 7 | B9: Shine On You Crazy Diamond (Pts. 1-5) | C9: Wish You Were Here | D9: Pink Floyd | E9: progressive rock, art rock | G9: Géneros: separados por comas
A10: 8 | B10: Nude | C10: In Rainbows | D10: Radiohead | E10: art rock, alternative rock | G10: MAYÚSCULAS = género padre (ej: METAL)
A11: 9 | B11: Jigsaw Fallin Into Place | C11: In Rainbows | D11: Radiohead | E11: art rock, alternative rock | G11: minúsculas = subgénero (ej: thrash metal)
A12: 10 | B12: Paranoid Android | C12: OK Computer | D12: Radiohead | E12: art rock, alternative rock
A13: 11 | B13: Let Down | C13: OK Computer | D13: Radiohead | E13: art rock, alternative rock
A14: 12 | B14: Sleep | C14: Lift Yr. Skinny Fists Like Antennas to Heaven! | D14: Godspeed You! Black Emperor | E14: post rock
A15: 13 | B15: The Great Gig in the Sky | C15: The Dark Side Of The Moon | D15: Pink Floyd | E15: progressive rock, psychedelic rock
A16: 14 | B16: Time | C16: The Dark Side Of The Moon | D16: Pink Floyd | E16: progressive rock, psychedelic rock
A17: 15 | B17: Rosetta Stoned | C17: 10,000 Days | D17: TOOL | E17: progressive metal, alternative metal
A18: 16 | B18: Vicarious | C18: 10,000 Days | D18: TOOL | E18: progressive metal, alternative metal
A19: 17 | B19: Forty Six & 2 | C19: Ænima | D19: TOOL | E19: progressive metal, alternative metal
A20: 18 | B20: Eulogy | C20: Ænima | D20: TOOL | E20: progressive metal, alternative metal
A21: 19 | B21: Cuarto movimiento: la realidad | C21: La ley innata | D21: Extremoduro | E21: hard rock, progressive rock
A22: 20 | B22: Dogs | C22: Animals | D22: Pink Floyd | E22: progressive rock, psychedelic rock
A23: 21 | B23: Stairway to Heaven | C23: Led Zeppelin IV | D23: Led Zeppelin | E23: classic rock
... A102: 100 | B102: Xtal | C102: Selected Ambient Works 85-92 | D102: Aphex Twin | E102: ambient techno, idm

Sheet TOP Generos
A1: TOP Rock (157 álbumes)
A2: # | B2: Artista | C2: Álbum | D2: Media | E2: 3rd EYE SCORE
A3: 1 | B3: Fishmans | C3: LONG SEASON | D3: 10.5 | E3: 10.85
A4: 2 | B4: Yes | C4: Close to the Edge | D4: 10 | E4: 10.44
A5: 3 | B5: Pink Floyd | C5: Wish You Were Here | D5: 10 | E5: 10.39
A6: 4 | B6: Radiohead | C6: In Rainbows | D6: 9.7 | E6: 10.37
A7: 5 | B7: Radiohead | C7: OK Computer | D7: 9.68 | E7: 10.07
A8: 6 | B8: Godspeed You! Black Emperor | C8: Lift Yr. Skinny Fists Like Antennas to Heaven! | D8: 9.88 | E8: 10.05
A9: 7 | B9: Pink Floyd | C9: The Dark Side Of The Moon | D9: 9.61 | E9: 10
A10: 8 | B10: Extremoduro | C10: La ley innata | D10: 9.5 | E10: 9.77
A11: 9 | B11: Pink Floyd | C11: Animals | D11: 9.4 | E11: 9.55
A12: 10 | B12: Led Zeppelin | C12: Led Zeppelin IV | D12: 9.38 | E12: 9.53
A13: 11 | B13: King Crimson | C13: In The Court Of The Crimson King | D13: 9.4 | E13: 9.46
A14: 12 | B14: Black Sabbath | C14: Paranoid | D14: 9.31 | E14: 9.43
... A97: 95 | B97: The Clash | C97: London Calling | D97: 8.55 | E97: 8.6
A98: 96 | B98: Foreigner | C98: 4 | D98: 8.6 | E98: 8.6
A99: 97 | B99: Caspian | C99: Dust and Disquiet | D99: 8.67 | E99: 8.57
A100: 98 | B100: Blue Öyster Cult | C100: Fire of Unknown Origin | D100: 8.67 | E100: 8.57
A101: 99 | B101: Coldplay | C101: X&Y | D101: 8.65 | E101: 8.56
A102: 100 | B102: Radiohead | C102: Hail To the Thief | D102: 8.5 | E102: 8.56
A103: 101 | B103: Sigur Rós | C103: Ágætis byrjun | D103: 8.67 | E103: 8.56
A104: 102 | B104: Boris | C104: Pink | D104: 8.65 | E104: 8.56
A105: 103 | B105: Led Zeppelin | C105: Led Zeppelin III | D105: 8.6 | E105: 8.54
A106: 104 | B106: The Smile | C106: Wall Of Eyes | D106: 8.63 | E106: 8.53
A107: 105 | B107: Swans | C107: Soundtracks for the Blind | D107: 8.61 | E107: 8.52
A108: 106 | B108: La Paloma | C108: Una idea, pero es triste [EP] | D108: 8.6 | E108: 8.52
A109: 107 | B109: Beach House | C109: Bloom | D109: 8.6 | E109: 8.52
A110: 108 | B110: Oasis | C110: Definitely Maybe | D110: 8.59 | E110: 8.51
... A159: 157 | B159: Benson Boone | C159: American Heart | D159: 2.5 | E159: 2.39
A161: TOP Metal (92 álbumes)
A162: # | B162: Artista | C162: Álbum | D162: Media | E162: 3rd EYE SCORE
A163: 1 | B163: TOOL | C163: Lateralus | D163: 10.11 | E163: 10.99
A164: 2 | B164: TOOL | C164: 10,000 Days | D164: 9.61 | E164: 9.99
A165: 3 | B165: TOOL | C165: Ænima | D165: 9.61 | E165: 9.96
A166: 4 | B166: TOOL | C166: Salival [LIVE] | D166: 9.25 | E166: 9.53
A167: 5 | B167: Opeth | C167: Blackwater Park | D167: 9.29 | E167: 9.44
A168: 6 | B168: Black Sabbath | C168: Paranoid | D168: 9.31 | E168: 9.43
A169: 7 | B169: TOOL | C169: Fear Inoculum | D169: 9.29 | E169: 9.42
A170: 8 | B170: Metallica | C170: Master Of Puppets | D170: 9.25 | E170: 9.37
A171: 9 | B171: Opeth | C171: Ghost Reveries | D171: 9.13 | E171: 9.24
...

Sheet Mapeo Generos
A1: SUBGÉNERO | B1: GÉNERO PADRE | C1: GÉNEROS ÚNICOS | E1: NOTAS
A2: alt pop | B2: pop | C2: ambient | E2: La columa de Subgenero se rellena automaticamente, coge los subgeneros de la tabla de la hoja Tabla Albums
A3: alternative dance | B3: electronic | C3: electronic
A4: alternative metal | B4: metal | C4: folk | E4: Manualmente se rellana la columa a su derecha, para asociar subgéneros con géneros padre
A5: alternative R&B | B5: r&b | C5: hip hop
A6: alternative rock | B6: rock | C6: industrial & noise | E6: Entonces si se ha incluido un subgenero nuevo, hay que introducir su asociación.
A7: ambient | B7: ambient | C7: jazz
A8: ambient pop | B8: pop | C8: metal | E8: Si ningún genero padre existente aplica (la tercera columna), se puede incluir un nuevo género padre,
A9: ambient techno | B9: electronic | C9: new age | E9: (automaticamente se pondrá en la tercera columna)
A10: andalusian rock | B10: rock | C10: pop
A11: aor | B11: rock | C11: psychedelia | E11: La tercera columna es simplemente de referencia, para saber que generos padres existen
A12: art pop | B12: pop | C12: punk
A13: art rock | B13: rock | C13: r&b
A14: atmospheric black metal | B14: metal | C14: regional music
A15: atmospheric sludge metal | B15: metal | C15: rock
A16: avant prog | B16: rock | C16: singer-songwriter
A17: baggy | B17: rock | C17: soundtrack
A18: big beat | B18: electronic
A19: black metal | B19: metal
A20: blackgaze | B20: metal
A21: blues rock | B21: rock
A22: boom bap | B22: hip hop
A23: britpop | B23: rock
A24: brutal death metal | B24: metal
A25: brutal prog | B25: metal
A26: chamber folk | B26: folk
A27: chipmunk soul | B27: hip hop
A28: city pop | B28: pop
A29: classic rock | B29: rock
... A165: funk | B165: rock
A166: ethereal wave

Sheet Graficos
AT1: Mes | AU1: Reviews acumuladas
AT2: 2026-01 | AU2: 42
AT3: 2026-02 | AU3: 78
AT4: 2026-03 | AU4: 119
AT5: 2026-04 | AU5: 152
AT6: 2026-05 | AU6: 192
AT7: 2026-06 | AU7: 232
AT8: 2026-07 | AU8: 271
AT9: 2026-08 | AU9: 289
AT10: 2026-09 | AU10: 316
AT11: 2026-10 | AU11: 319
AT14: Mes | AU14: Reviews del mes
AT15: 2026-01 | AU15: 42
AT16: 2026-02 | AU16: 36
AT17: 2026-03 | AU17: 41
AT18: 2026-04 | AU18: 33
AT19: 2026-05 | AU19: 40
AT20: 2026-06 | AU20: 40
AT21: 2026-07 | AU21: 39
AT22: 2026-08 | AU22: 18
AT23: 2026-09 | AU23: 27
AT24: 2026-10 | AU24: 3
AT27: Fecha de review | AU27: Media acumulada | AV27: 3rd EYE acumulado | AW27: Media últimos 20
AT28: 17/01/2026 | AU28: 8.88 | AV28: 9.14 | AW28: 8.88
AT29: 17/01/2026 | AU29: 9.02 | AV29: 9.19 | AW29: 9.02
AT30: 17/01/2026 | AU30: 9.01 | AV30: 9.15 | AW30: 9.01
AT31: 17/01/2026 | AU31: 8.99 | AV31: 9.12 | AW31: 8.99
AT32: 17/01/2026 | AU32: 8.95 | AV32: 9.03 | AW32: 8.95
AT33: 17/01/2026 | AU33: 8.86 | AV33: 8.92 | AW33: 8.86
AT34: 17/01/2026 | AU34: 8.86 | AV34: 8.91 | AW34: 8.86
AT35: 17/01/2026 | AU35: 8.92 | AV35: 8.98 | AW35: 8.92
AT36: 18/01/2026 | AU36: 8.99 | AV36: 9.09 | AW36: 8.99
AT37: 18/01/2026 | AU37: 9.02 | AV37: 9.12 | AW37: 9.02
AT38: 18/01/2026 | AU38: 9.05 | AV38: 9.15 | AW38: 9.05
AT39: 18/01/2026 | AU39: 9.07 | AV39: 9.16 | AW39: 9.07
... AT346: 05/10/2026 | AU346: 8.55 | AV346: 8.52 | AW346: 8.2
AT349: Mes | AU349: Media del mes
AT350: 2026-01 | AU350: 8.73
AT351: 2026-02 | AU351: 8.78
AT352: 2026-03 | AU352: 8.53
...

Sheet Resumen
A1: RESUMEN GLOBAL
A2: GENERAL
A3: Total álbumes | B3: 319
A4: Artistas únicos | B4: 196
A5: Total canciones | B5: 3385
A6: Canciones con nota | B6: 3230
A7: Interludios | B7: 155
A8: Canciones/álbum (media) | B8: 10.61
A9: % Interludios | B9: 0.0458
A11: NOTAS - TENDENCIA CENTRAL
A12: Media global | B12: 8.5
A13: Mediana global | B13: 8.5
A14: Moda (nota más frecuente) | B14: 8 (×790)
A16: NOTAS - DISPERSIÓN
A17: Desviación típica | B17: 1.16
A18: Coef. de variación | B18: 0.1368
A19: Rango (máx - mín) | B19: 10.5 (0 - 10.5)
A20: Rango intercuartílico (Q3-Q1) | B20: 1 (8 - 9)
A22: NOTAS - FORMA DE LA DISTRIBUCIÓN
A23: Asimetría (skewness) | B23: -2 ← sesgo alto
A24: Curtosis (excess) | B24: 11.21 ← colas pesadas
A26: DISTRIBUCIÓN POR RANGOS
A27: [0, 5) | B27: 41 (1.27%)
A28: [5, 7) | B28: 63 (1.95%)
A29: [7, 8) | B29: 397 (12.29%)
A30: [8, 9) | B30: 1513 (46.84%)
A31: [9, 10) | B31: 737 (22.82%)
A32: [10, 10.5] | B32: 479(14.83%)
A34: DESTACADOS
A35: Mejor álbum | B35: Fishmans - LONG SEASON (10.5)
A36: Peor álbum | B36: Hobo Johnson - Hobo Johnson Alienates His Fanbase (0.81)
A37: Más consistente (menor desv.) | B37: Lady Twostar - The Great Plains (σ=0.24)
A38: Más irregular (mayor desv.) | B38: Imagine Dragons - Evolve (σ=1.98)
A40: SUBGÉNEROS
A41: Álbumes con subgénero | B41: 319 de 319
A42: Subgéneros únicos | B42: 157
A43: Más frecuente | B43: progressive rock (35)
A44: Mejor media | B44: alt country (9.25)
A45: Peor media | B45: comedy rap (0.81)
A47: DESGLOSE POR SUBGÉNERO
...

Sheet video
B1: song | C1: commentary | D1: genre | E1: album | F1: artist | G1: year
A2: 1 | B2: Close to the Edge | C2: Music doesn't get better than this | D2: =VLOOKUP(E2,'Tabla Albums'!C:L,9,FALSE) -> progressive rock | E2: Close to the Edge | F2: Yes | G2: 1972
A3: 2 | B3: Reflection | C3: TOOL is the closest thing I've ever had to a true spiritual experience | D3: =VLOOKUP(E3,'Tabla Albums'!C:L,9,FALSE) -> progressive metal, alternative metal | E3: Lateralus | F3: TOOL | G3: =VLOOKUP(E3,'Tabla Albums'!C:L,10,FALSE) -> 2001
A4: 3 | B4: Weird Fishes / Arpeggi | C4: There is nothing more beautiful in the entire world than this song. Makes me cry instantly. | D4: =VLOOKUP(E4,'Tabla Albums'!C:L,9,FALSE) -> art rock, alternative rock | E4: In Rainbows | F4: Radiohead | G4: =VLOOKUP(E4,'Tabla Albums'!C:L,10,FALSE) -> 2007
A5: 4 | B5: Cuarto movimiento: la realidad | C5: This album thouches my soul in places no other album can | D5: =VLOOKUP(E5,'Tabla Albums'!C:L,9,FALSE) -> hard rock, progressive rock | E5: La ley innata | F5: Extremoduro | G5: =VLOOKUP(E5,'Tabla Albums'!C:L,10,FALSE) -> 2008
A6: 5 | B6: Sleep | C6: Music so out of this world I don't feel like I deserve to listen to it | D6: =VLOOKUP(E6,'Tabla Albums'!C:L,9,FALSE) -> post rock | E6: Lift Yr. Skinny Fists Like Antennas to Heaven! | F6: Godspeed You! Black Emperor | G6: =VLOOKUP(E6,'Tabla Albums'!C:L,10,FALSE) -> 2000
A7: 6 | B7: Siberian Khatru | C7: The levels of dopamine this song gives me cannot be healthy | D7: =VLOOKUP(E7,'Tabla Albums'!C:L,9,FALSE) -> progressive rock | E7: Close to the Edge | F7: Yes | G7: =VLOOKUP(E7,'Tabla Albums'!C:L,10,FALSE) -> 1972
A8: 7 | B8: Ghost of Perdition | C8: The most complete metal song ever made. Masterpiece among masterpieces. | D8: =VLOOKUP(E8,'Tabla Albums'!C:L,9,FALSE) -> progressive metal, death metal | E8: Ghost Reveries | F8: Opeth | G8: =VLOOKUP(E8,'Tabla Albums'!C:L,10,FALSE) -> 2005
A9: 8 | B9: Pigs (Three Different Ones) | C9: Holy fucking solo. Pink Floyd's best album. | D9: =VLOOKUP(E9,'Tabla Albums'!C:L,9,FALSE) -> progressive rock, psychedelic rock | E9: Animals | F9: Pink Floyd | G9: =VLOOKUP(E9,'Tabla Albums'!C:L,10,FALSE) -> 1977
A10: 9 | B10: I Don't Love | C10: Why do I connect so deeply with depressing music if I'm such a happy person? | D10: =VLOOKUP(E10,'Tabla Albums'!C:L,9,FALSE) -> shoegaze, slowcore | E10: Deathconsciousness | F10: Have A Nice Life | G10: =VLOOKUP(E10,'Tabla Albums'!C:L,10,FALSE) -> 2008
A11: 10 | B11: Motion Picture Soundtrack | C11: I still don't know how toavoid crying to this song | D11: =VLOOKUP(E11,'Tabla Albums'!C:L,9,FALSE) -> art rock, electronic | E11: Kid A | F11: Radiohead | G11: =VLOOKUP(E11,'Tabla Albums'!C:L,10,FALSE) -> 2000
A12: 11 | B12: Eclipse | C12: Perfect closure of a perfect album | D12: =VLOOKUP(E12,'Tabla Albums'!C:L,9,FALSE) -> progressive rock, psychedelic rock | E12: The Dark Side Of The Moon | F12: Pink Floyd | G12: =VLOOKUP(E12,'Tabla Albums'!C:L,10,FALSE) -> 1973
A13: 12 | B13: Right In Two | C13: TOOL will always be my favorite band of all time | D13: =VLOOKUP(E13,'Tabla Albums'!C:L,9,FALSE) -> progressive metal, alternative metal | E13: 10,000 Days | F13: TOOL | G13: =VLOOKUP(E13,'Tabla Albums'!C:L,10,FALSE) -> 2006
A14: 13 | B14: Face of Melinda | C14: Once you acquire the taste for Opeth, there's no going back | D14: =VLOOKUP(E14,'Tabla Albums'!C:L,9,FALSE) -> progressive metal, death metal | E14: Still Life | F14: Opeth | G14: =VLOOKUP(E14,'Tabla Albums'!C:L,10,FALSE) -> 1999
... A26: 25 | B26: Way Out Of Here | C26: I'd put Anesthetize here but I already put it in my other top 100 songs video | D26: =VLOOKUP(E26,'Tabla Albums'!C:L,9,FALSE) -> progressive rock, progressive metal | E26: Fear of a Blank Planet | F26: Porcupine Tree | G26: =VLOOKUP(E26,'Tabla Albums'!C:L,10,FALSE) -> 2007
A27: 26 | B27: Tunnel of Love | C27: Their most emotional song, and my most listened song by them | D27: pop rock | E27: Tunnel of Love | F27: Dire Straits | G27: 1980
A28: 27 | B28: Fade to Black | C28: This was my favorite song of all time for a very long time | D28: =VLOOKUP(E28,'Tabla Albums'!C:L,9,FALSE) -> thrash metal | E28: Ride The Lightning | F28: Metallica | G28: =VLOOKUP(E28,'Tabla Albums'!C:L,10,FALSE) -> 1984
A29: 28 | B29: Windowlicker | C29: Electronic music's Stairway to Heaven | D29: =VLOOKUP(E29,'Tabla Albums'!C:L,9,FALSE) -> idm | E29: Windowlicker [SINGLE] | F29: Aphex Twin | G29: =VLOOKUP(E29,'Tabla Albums'!C:L,10,FALSE) -> 1995
A30: 29 | B30: Resurrections | C30: Celeste wouldn't be such a masterpiece if it weren't for its music | D30: videogame music | E30: Celest OST | F30: Lena Raine | G30: 2018
A31: 30 | B31: Indiscipline | C31: Insane drumming | D31: =VLOOKUP(E31,'Tabla Albums'!C:L,9,FALSE) -> progressive rock, art rock | E31: Discipline | F31: King Crimson | G31: =VLOOKUP(E31,'Tabla Albums'!C:L,10,FALSE) -> 1981
A32: 31 | B32: Somewhere I Belong | C32: The only kind of nu metal that I really dig | D32: =VLOOKUP(E32,'Tabla Albums'!C:L,9,FALSE) -> nu metal, rap metal | E32: Meteora | F32: Linkin Park | G32: =VLOOKUP(E32,'Tabla Albums'!C:L,10,FALSE) -> 2003
A33: 32 | B33: Si te vas… | C33: If Extremoduro were american, they'd be globally famous | D33: =VLOOKUP(E33,'Tabla Albums'!C:L,9,FALSE) -> art rock | E33: Material Defectuoso | F33: Extremoduro | G33: =VLOOKUP(E33,'Tabla Albums'!C:L,10,FALSE) -> 2011
A34: 33 | B34: They’ll Only Miss You When You Leave | C34: Those violins destroy me | D34: =VLOOKUP(E34,'Tabla Albums'!C:L,9,FALSE) -> slowcore | E34: Songs About Leaving | F34: Carissa's Wierd | G34: =VLOOKUP(E34,'Tabla Albums'!C:L,10,FALSE) -> 2002
A35: 34 | B35: Choral Chambers | C35: Best track of both games | D35: videogame music | E35: Hollow Knight: Silksong | F35: Christopher Larkin | G35: 2025
A36: 35 | B36: Mercy Mercy Me (The Ecology) | C36: Absolutely timeless | D36: =VLOOKUP(E36,'Tabla Albums'!C:L,9,FALSE) -> soul, progressive soul | E36: What's Going On | F36: Marvin Gaye | G36: =VLOOKUP(E36,'Tabla Albums'!C:L,10,FALSE) -> 1979
A37: 36 | B37: Eventually | C37: When the synth finally breaks free…. sooo damn good | D37: =VLOOKUP(E37,'Tabla Albums'!C:L,9,FALSE) -> neo psychedelic, indie | E37: Currents | F37: Tame Impala | G37: =VLOOKUP(E37,'Tabla Albums'!C:L,10,FALSE) -> 2015
A38: 37 | B38: Darkness | C38: I love every inch of this album with all my soul | D38: =VLOOKUP(E38,'Tabla Albums'!C:L,9,FALSE) -> dream pop, indie pop | E38: You Will Never Know Why | F38: Sweet Trip | G38: =VLOOKUP(E38,'Tabla Albums'!C:L,10,FALSE) -> 2009
A39: 38 | B39: Living Mice | C39: I can't think of a modern artist that influenced more childhoods | D39: =VLOOKUP(E39,'Tabla Albums'!C:L,9,FALSE) -> ambient, video game music | E39: Minecraft Volume Alpha [OST] | F39: C418 | G39: =VLOOKUP(E39,'Tabla Albums'!C:L,10,FALSE) -> 2011
A40: 39 | B40: Catch The Rainbow | C40: The bassline, the drumming, the slow pacing… masterpiece | D40: Psychedelic Rock | E40: Ritchie Blackmore's Rainbow | F40: Rainbow | G40: 1975
A41: 40 | B41: Alive | C41: Best grunge singer. Fight me. | D41: =VLOOKUP(E41,'Tabla Albums'!C:L,9,FALSE) -> grunge, alternative rock | E41: Ten | F41: Pearl Jam | G41: =VLOOKUP(E41,'Tabla Albums'!C:L,10,FALSE) -> 1991
A42: 41 | B42: Cloudbusting | C42: I wish I had just a fraction of Kate Bush's talent | D42: =VLOOKUP(E42,'Tabla Albums'!C:L,9,FALSE) -> art pop, progressive pop | E42: Hounds of Love | F42: Kate Bush | G42: =VLOOKUP(E42,'Tabla Albums'!C:L,10,FALSE) -> 1985
A43: 42 | B43: I Don't Want It | C43: The only guitar solo that always makes me cry | D43: =VLOOKUP(E43,'Tabla Albums'!C:L,9,FALSE) -> neo psychedelic, art rock | E43: Quebec | F43: Ween | G43: =VLOOKUP(E43,'Tabla Albums'!C:L,10,FALSE) -> 2003
A44: 43 | B44: Firth of Fifth | C44: Progressive rock at its finest | D44: =VLOOKUP(E44,'Tabla Albums'!C:L,9,FALSE) -> progressive rock, symphonic prog | E44: Selling England by the Pound | F44: Genesis | G44: =VLOOKUP(E44,'Tabla Albums'!C:L,10,FALSE) -> 1973
A45: 44 | B45: The Rain Song | C45: This song comes from Heaven | D45: =VLOOKUP(E45,'Tabla Albums'!C:L,9,FALSE) -> hard rock | E45: Houses of the Holy | F45: Led Zeppelin | G45: =VLOOKUP(E45,'Tabla Albums'!C:L,10,FALSE) -> 1973
A46: 45 | B46: Cry For Me | C46: Why is this so damn good | D46: =VLOOKUP(E46,'Tabla Albums'!C:L,9,FALSE) -> neo psychedelic, synthpop | E46: Imaginal Disk | F46: Magdalena Bay | G46: =VLOOKUP(E46,'Tabla Albums'!C:L,10,FALSE) -> 2024
A47: 46 | B47: Gimme Shelter | C47: Those voice cracks give me the biggest chills. Legendary track. | D47: =VLOOKUP(E47,'Tabla Albums'!C:L,9,FALSE) -> blues rock, country rock | E47: Let It Bleed | F47: The Rolling Stones | G47: =VLOOKUP(E47,'Tabla Albums'!C:L,10,FALSE) -> 1969
A48: 47 | B48: The Rainbow | C48: This is the purest definition of art | D48: =VLOOKUP(E48,'Tabla Albums'!C:L,9,FALSE) -> post rock, art rock | E48: Spirit of Eden | F48: Talk Talk | G48: =VLOOKUP(E48,'Tabla Albums'!C:L,10,FALSE) -> 1988
A49: 48 | B49: The Final Thing on My Mind | C49: Whole songs feels like a buildup that explodes beautifully | D49: =VLOOKUP(E49,'Tabla Albums'!C:L,9,FALSE) -> progressive rock | E49: Your Wilderness | F49: The Pineapple Thief | G49: =VLOOKUP(E49,'Tabla Albums'!C:L,10,FALSE) -> 2016
A50: 49 | B50: P.Y.T. (Pretty Young Thing) | C50: That high pitched voice in the background scratches my brain sooo good | D50: =VLOOKUP(E50,'Tabla Albums'!C:L,9,FALSE) -> contemporary r&b, dance pop | E50: Thriller | F50: Michael Jackson | G50: =VLOOKUP(E50,'Tabla Albums'!C:L,10,FALSE) -> 1982
A51: 50 | B51: I Want You (She's So Heavy) | C51: I'll never forget the first time I listened the outro of this song | D51: blues rock | E51: Abbey Road | F51: The Beatles | G51: =VLOOKUP(E51,'Tabla Albums'!C:L,10,FALSE) -> 1969
...
